<?xml version="1.0"?>
<robot name="slatol_mu_0.05">

  <link name="base_link">
    <inertial>
      <origin xyz="0 0 0" rpy="0 0 0"/>
      <mass value="0.9500"/>
      <inertia ixx="0.001583" ixy="0" ixz="0"
               iyy="0.003958" iyz="0"
               izz="0.003958"/>
    </inertial>
    <visual>
      <origin xyz="0 0 0" rpy="0 0 0"/>
      <geometry><box size="0.2 0.1 0.1"/></geometry>
      <material name="blue"><color rgba="0.2 0.3 0.8 1.0"/></material>
    </visual>
    <collision>
      <origin xyz="0 0 0" rpy="0 0 0"/>
      <geometry><box size="0.2 0.1 0.1"/></geometry>
    </collision>
  </link>

  <joint name="hip_joint" type="revolute">
    <parent link="base_link"/>
    <child link="femur_link"/>
    <origin xyz="0 0 -0.05" rpy="0 0 0"/>
    <axis xyz="0 1 0"/>
    <limit lower="-1.5708" upper="1.5708" effort="5.0" velocity="22.0"/>
    <dynamics damping="0.1" friction="0.01"/>
  </joint>

  <link name="femur_link">
    <inertial>
      <origin xyz="0 0 -0.075" rpy="0 0 0"/>
      <mass value="0.0250"/>
      <inertia ixx="0.000049" ixy="0" ixz="0"
               iyy="0.000049" iyz="0"
               izz="0.000005"/>
    </inertial>
    <visual>
      <origin xyz="0 0 -0.075" rpy="0 0 0"/>
      <geometry><cylinder length="0.15" radius="0.02"/></geometry>
      <material name="red"><color rgba="0.8 0.2 0.2 1.0"/></material>
    </visual>
    <collision>
      <origin xyz="0 0 -0.075" rpy="0 0 0"/>
      <geometry><cylinder length="0.15" radius="0.02"/></geometry>
    </collision>
  </link>

  <joint name="knee_joint" type="revolute">
    <parent link="femur_link"/>
    <child link="tibia_link"/>
    <origin xyz="0 0 -0.15" rpy="0 0 0"/>
    <axis xyz="0 1 0"/>
    <limit lower="-2.618" upper="0.0" effort="5.0" velocity="22.0"/>
    <dynamics damping="0.1" friction="0.01"/>
  </joint>

  <link name="tibia_link">
    <inertial>
      <origin xyz="0 0 -0.075" rpy="0 0 0"/>
      <mass value="0.0250"/>
      <inertia ixx="0.000049" ixy="0" ixz="0"
               iyy="0.000049" iyz="0"
               izz="0.000005"/>
    </inertial>
    <visual>
      <origin xyz="0 0 -0.075" rpy="0 0 0"/>
      <geometry><cylinder length="0.15" radius="0.02"/></geometry>
      <material name="red"><color rgba="0.8 0.2 0.2 1.0"/></material>
    </visual>
    <collision>
      <origin xyz="0 0 -0.075" rpy="0 0 0"/>
      <geometry><cylinder length="0.15" radius="0.02"/></geometry>
    </collision>
  </link>

  <joint name="foot_joint" type="fixed">
    <parent link="tibia_link"/>
    <child link="foot_link"/>
    <origin xyz="0 0 -0.15" rpy="0 0 0"/>
  </joint>

  <link name="foot_link">
    <inertial>
      <origin xyz="0 0 0" rpy="0 0 0"/>
      <mass value="0.0010"/>
      <inertia ixx="0.000000" ixy="0" ixz="0"
               iyy="0.000000" iyz="0"
               izz="0.000000"/>
    </inertial>
    <visual>
      <geometry><sphere radius="0.02"/></geometry>
      <material name="black"><color rgba="0.1 0.1 0.1 1.0"/></material>
    </visual>
    <collision>
      <geometry><sphere radius="0.02"/></geometry>
    </collision>
  </link>

</robot>