<?xml version="1.0"?>
<robot name="slatol">
  <link name="base_link">
    <inertial>
      <origin xyz="0 0 0" rpy="0 0 0"/>
      <mass value="0.95"/>
      <inertia ixx="0.005" ixy="0" ixz="0" iyy="0.005" iyz="0" izz="0.005"/>
    </inertial>
    <visual>
      <origin xyz="0 0 0" rpy="0 0 0"/>
      <geometry><box size="0.2 0.1 0.1"/></geometry>
      <material name="blue"><color rgba="0.2 0.2 0.8 1"/></material>
    </visual>
    <collision>
      <origin xyz="0 0 0" rpy="0 0 0"/>
      <geometry><box size="0.2 0.1 0.1"/></geometry>
    </collision>
  </link>

  <link name="femur">
    <inertial>
      <origin xyz="0 0 -0.075" rpy="0 0 0"/> <mass value="0.025"/>
      <inertia ixx="0.0005" ixy="0" ixz="0" iyy="0.0005" iyz="0" izz="0.0001"/>
    </inertial>
    <visual>
      <origin xyz="0 0 -0.075" rpy="0 0 0"/>
      <geometry><cylinder radius="0.02" length="0.15"/></geometry>
      <material name="gray"><color rgba="0.5 0.5 0.5 1"/></material>
    </visual>
    <collision>
      <origin xyz="0 0 -0.075" rpy="0 0 0"/>
      <geometry><cylinder radius="0.02" length="0.15"/></geometry>
    </collision>
  </link>

  <link name="tibia">
    <inertial>
      <origin xyz="0 0 -0.075" rpy="0 0 0"/> <mass value="0.025"/>
      <inertia ixx="0.0005" ixy="0" ixz="0" iyy="0.0005" iyz="0" izz="0.0001"/>
    </inertial>
    <visual>
      <origin xyz="0 0 -0.075" rpy="0 0 0"/>
      <geometry><cylinder radius="0.02" length="0.15"/></geometry>
      <material name="red"><color rgba="0.8 0.2 0.2 1"/></material>
    </visual>
    <collision>
      <origin xyz="0 0 -0.075" rpy="0 0 0"/>
      <geometry><cylinder radius="0.02" length="0.15"/></geometry>
    </collision>
  </link>

  <joint name="hip_joint" type="continuous">
    <parent link="base_link"/>
    <child link="femur"/>
    <origin xyz="0 0 -0.05" rpy="0 0 0"/>
    <axis xyz="0 1 0"/>
    <dynamics damping="0.1" friction="0.0"/>
  </joint>

  <joint name="knee_joint" type="revolute">
    <parent link="femur"/>
    <child link="tibia"/>
    <origin xyz="0 0 -0.15" rpy="0 0 0"/>
    <axis xyz="0 1 0"/>
    <limit lower="-2.61" upper="0" effort="5.0" velocity="22.0"/>
    <dynamics damping="0.1" friction="0.0"/>
  </joint>
</robot>
